Workbook
Name Developer_Salaries___Norway_2024: 'data input'!$A$1:$A$2683
Name experience: 'Developers salary'!$L$4
Name fylke: 'Developers salary'!$J$4
Name title: 'Developers salary'!$D$4

Sheet data input
C1: kjønn | D1: utdanning | E1: erfaring | F1: arbeidssted | G1: arbeidssituasjon | H1: fag | I1: lønn | J1: bonus? | K1: Lønn, numbers | L1: experience buckets | O1: years of experience | P1: bracket
C2: mann | D2: 4 | E2: 7 | F2: Agder | G2: "in-house: privat sektor" | H2: AI / maskinlæring | I2: 865000 | J2: Nei | K2: 865000 | L2: =_xlfn.XLOOKUP(E2,$P$2:$P$5,$O$2:$O$5,,1) -> 5 - 8 | N2: jun | O2: 0 - 4 | P2: 4
C3: mann | D3: 5 | E3: 2 | F3: Nordland | G3: "in-house: offentlig/kommunal sektor" | H3: AI / maskinlæring | I3: 756000 | J3: Nei | K3: 756000 | L3: =_xlfn.XLOOKUP(E3,$P$2:$P$5,$O$2:$O$5,,1) -> 0 - 4 | N3: intemid | O3: 5 - 8 | P3: 8
C4: mann | D4: 4 | E4: 30 | F4: Oslo | G4: konsulent | H4: AI / maskinlæring | I4: 1500000 | J4: Nei | K4: 1500000 | L4: =_xlfn.XLOOKUP(E4,$P$2:$P$5,$O$2:$O$5,,1) -> 15 + | N4: mid | O4: 9 - 14 | P4: 14
C5: mann | D5: 5 | E5: 25 | F5: Oslo | G5: konsulent | H5: AI / maskinlæring | I5: 1200000 | J5: Nei | K5: 1200000 | L5: =_xlfn.XLOOKUP(E5,$P$2:$P$5,$O$2:$O$5,,1) -> 15 + | N5: seniour | O5: 15 + | P5: 50
C6: mann | D6: 9 | E6: 18 | F6: Oslo | G6: "in-house: privat sektor" | H6: AI / maskinlæring | I6: 1200000 | J6: Nei | K6: 1200000 | L6: =_xlfn.XLOOKUP(E6,$P$2:$P$5,$O$2:$O$5,,1) -> 15 +
C7: mann | D7: 2 | E7: 14 | F7: Oslo | G7: "in-house: privat sektor" | H7: AI / maskinlæring | I7: 839000 | J7: Nei | K7: 839000 | L7: =_xlfn.XLOOKUP(E7,$P$2:$P$5,$O$2:$O$5,,1) -> 9 - 14
C8: kvinne | D8: 5 | E8: 9 | F8: Oslo | G8: konsulent | H8: AI / maskinlæring | I8: 1200000 | J8: Ja | K8: 1200000 | L8: =_xlfn.XLOOKUP(E8,$P$2:$P$5,$O$2:$O$5,,1) -> 9 - 14
C9: mann | D9: 6 | E9: 9 | F9: Oslo | G9: "in-house: privat sektor" | H9: AI / maskinlæring | I9: 980000 | J9: Ja | K9: 980000 | L9: =_xlfn.XLOOKUP(E9,$P$2:$P$5,$O$2:$O$5,,1) -> 9 - 14
C10: annet / ønsker ikke oppgi | D10: 5 | E10: 5 | F10: Oslo | G10: "in-house: privat sektor" | H10: AI / maskinlæring | I10: 750000 | J10: Nei | K10: 750000 | L10: =_xlfn.XLOOKUP(E10,$P$2:$P$5,$O$2:$O$5,,1) -> 5 - 8
C11: mann | D11: 5 | E11: 5 | F11: Oslo | G11: konsulent | H11: AI / maskinlæring | I11: 910000 | J11: Nei | K11: 910000 | L11: =_xlfn.XLOOKUP(E11,$P$2:$P$5,$O$2:$O$5,,1) -> 5 - 8
C12: mann | D12: 5 | E12: 4 | F12: Oslo | G12: konsulent | H12: AI / maskinlæring | I12: 820000 | J12: Nei | K12: 820000 | L12: =_xlfn.XLOOKUP(E12,$P$2:$P$5,$O$2:$O$5,,1) -> 0 - 4
C13: mann | D13: 5 | E13: 4 | F13: Oslo | G13: konsulent | H13: AI / maskinlæring | I13: 850000 | J13: Ja | K13: 850000 | L13: =_xlfn.XLOOKUP(E13,$P$2:$P$5,$O$2:$O$5,,1) -> 0 - 4
C14: mann | D14: 5 | E14: 3 | F14: Oslo | G14: konsulent | H14: AI / maskinlæring | I14: 730000 | J14: Ja | K14: 730000 | L14: =_xlfn.XLOOKUP(E14,$P$2:$P$5,$O$2:$O$5,,1) -> 0 - 4
C15: mann | D15: 5 | E15: 3 | F15: Oslo | G15: "in-house: privat sektor" | H15: AI / maskinlæring | I15: 850000 | J15: Nei | K15: 850000 | L15: =_xlfn.XLOOKUP(E15,$P$2:$P$5,$O$2:$O$5,,1) -> 0 - 4
C16: mann | D16: 5 | E16: 2 | F16: Oslo | G16: "in-house: privat sektor" | H16: AI / maskinlæring | I16: 710000 | J16: Nei | K16: 710000 | L16: =_xlfn.XLOOKUP(E16,$P$2:$P$5,$O$2:$O$5,,1) -> 0 - 4
C17: mann | D17: 5 | E17: 2 | F17: Oslo | G17: "in-house: privat sektor" | H17: AI / maskinlæring | I17: 894000 | J17: Nei | K17: 894000 | L17: =_xlfn.XLOOKUP(E17,$P$2:$P$5,$O$2:$O$5,,1) -> 0 - 4
... C2683: kvinne | D2683: 3 | E2683: 1 | F2683: Viken | G2683: "in-house: privat sektor" | H2683: UX / design | I2683: 665000 | J2683: Nei | K2683: 665000 | L2683: =_xlfn.XLOOKUP(E2683,$P$2:$P$5,$O$2:$O$5,,1) -> 0 - 4
A2688: https://www.kode24.no/artikkel/her-er-lonnstallene-for-norske-utviklere-2024/203888

Sheet average salary country level
A1: arbeidssituasjon | B1: arbeidssted | C1: min salary | D1: max salary | E1: average salary
A2: {=_xlfn.UNIQUE('data input'!G2:G2683)} -> "in-house: privat sektor" | B2: {=_xlfn.UNIQUE('data input'!F2:F2683)} -> Agder | C2: =_xlfn.MINIFS('data input'!$K$2:$K$2683,'data input'!$F$2:$F$2683,'average salary country level'!B2) -> 300000 | D2: =_xlfn.MAXIFS('data input'!$K$2:$K$2683,'data input'!$F$2:$F$2683,'average salary country level'!B2) -> 1500000 | E2: =AVERAGEIFS('data input'!$K$2:$K$2683,'data input'!$F$2:$F$2683,'average salary country level'!B2) -> 794608.51
A3: "in-house: offentlig/kommunal sektor" | B3: Nordland | C3: =_xlfn.MINIFS('data input'!$K$2:$K$2683,'data input'!$F$2:$F$2683,'average salary country level'!B3) -> 480000 | D3: =_xlfn.MAXIFS('data input'!$K$2:$K$2683,'data input'!$F$2:$F$2683,'average salary country level'!B3) -> 2400000 | E3: =AVERAGEIFS('data input'!$K$2:$K$2683,'data input'!$F$2:$F$2683,'average salary country level'!B3) -> 816131.11
A4: konsulent | B4: Oslo | C4: =_xlfn.MINIFS('data input'!$K$2:$K$2683,'data input'!$F$2:$F$2683,'average salary country level'!B4) -> 429000 | D4: =_xlfn.MAXIFS('data input'!$K$2:$K$2683,'data input'!$F$2:$F$2683,'average salary country level'!B4) -> 2700000 | E4: =AVERAGEIFS('data input'!$K$2:$K$2683,'data input'!$F$2:$F$2683,'average salary country level'!B4) -> 921618.73
A5: frilans / selvstendig næringsdrivende | B5: Rogaland | C5: =_xlfn.MINIFS('data input'!$K$2:$K$2683,'data input'!$F$2:$F$2683,'average salary country level'!B5) -> 430000 | D5: =_xlfn.MAXIFS('data input'!$K$2:$K$2683,'data input'!$F$2:$F$2683,'average salary country level'!B5) -> 2400000 | E5: =AVERAGEIFS('data input'!$K$2:$K$2683,'data input'!$F$2:$F$2683,'average salary country level'!B5) -> 910580.94
B6: Troms og Finnmark | C6: =_xlfn.MINIFS('data input'!$K$2:$K$2683,'data input'!$F$2:$F$2683,'average salary country level'!B6) -> 540000 | D6: =_xlfn.MAXIFS('data input'!$K$2:$K$2683,'data input'!$F$2:$F$2683,'average salary country level'!B6) -> 1650000 | E6: =AVERAGEIFS('data input'!$K$2:$K$2683,'data input'!$F$2:$F$2683,'average salary country level'!B6) -> 808402.78
B7: Trøndelag | C7: =_xlfn.MINIFS('data input'!$K$2:$K$2683,'data input'!$F$2:$F$2683,'average salary country level'!B7) -> 500000 | D7: =_xlfn.MAXIFS('data input'!$K$2:$K$2683,'data input'!$F$2:$F$2683,'average salary country level'!B7) -> 2100000 | E7: =AVERAGEIFS('data input'!$K$2:$K$2683,'data input'!$F$2:$F$2683,'average salary country level'!B7) -> 848503.61
B8: Vestland | C8: =_xlfn.MINIFS('data input'!$K$2:$K$2683,'data input'!$F$2:$F$2683,'average salary country level'!B8) -> 310000 | D8: =_xlfn.MAXIFS('data input'!$K$2:$K$2683,'data input'!$F$2:$F$2683,'average salary country level'!B8) -> 2500000 | E8: =AVERAGEIFS('data input'!$K$2:$K$2683,'data input'!$F$2:$F$2683,'average salary country level'!B8) -> 857949.8
B9: Viken | C9: =_xlfn.MINIFS('data input'!$K$2:$K$2683,'data input'!$F$2:$F$2683,'average salary country level'!B9) -> 420000 | D9: =_xlfn.MAXIFS('data input'!$K$2:$K$2683,'data input'!$F$2:$F$2683,'average salary country level'!B9) -> 2600000 | E9: =AVERAGEIFS('data input'!$K$2:$K$2683,'data input'!$F$2:$F$2683,'average salary country level'!B9) -> 940998.15
B10: Innlandet | C10: =_xlfn.MINIFS('data input'!$K$2:$K$2683,'data input'!$F$2:$F$2683,'average salary country level'!B10) -> 415000 | D10: =_xlfn.MAXIFS('data input'!$K$2:$K$2683,'data input'!$F$2:$F$2683,'average salary country level'!B10) -> 1600000 | E10: =AVERAGEIFS('data input'!$K$2:$K$2683,'data input'!$F$2:$F$2683,'average salary country level'!B10) -> 870460.61
B11: utlandet | C11: =_xlfn.MINIFS('data input'!$K$2:$K$2683,'data input'!$F$2:$F$2683,'average salary country level'!B11) -> 500000 | D11: =_xlfn.MAXIFS('data input'!$K$2:$K$2683,'data input'!$F$2:$F$2683,'average salary country level'!B11) -> 2206000 | E11: =AVERAGEIFS('data input'!$K$2:$K$2683,'data input'!$F$2:$F$2683,'average salary country level'!B11) -> 1129829.9
B12: Vestfold og Telemark | C12: =_xlfn.MINIFS('data input'!$K$2:$K$2683,'data input'!$F$2:$F$2683,'average salary country level'!B12) -> 450000 | D12: =_xlfn.MAXIFS('data input'!$K$2:$K$2683,'data input'!$F$2:$F$2683,'average salary country level'!B12) -> 1700000 | E12: =AVERAGEIFS('data input'!$K$2:$K$2683,'data input'!$F$2:$F$2683,'average salary country level'!B12) -> 830742.8
B13: Møre og Romsdal | C13: =_xlfn.MINIFS('data input'!$K$2:$K$2683,'data input'!$F$2:$F$2683,'average salary country level'!B13) -> 500000 | D13: =_xlfn.MAXIFS('data input'!$K$2:$K$2683,'data input'!$F$2:$F$2683,'average salary country level'!B13) -> 1200000 | E13: =AVERAGEIFS('data input'!$K$2:$K$2683,'data input'!$F$2:$F$2683,'average salary country level'!B13) -> 806157.02
B20: Akershus | C20: 794608.51
B21: Agder | C21: =E2 -> 794608.51
B22: Buskerud | C22: =E9 -> 940998.15
B23: Finnmark | C23: =E6 -> 808402.78
B24: Innlandet | C24: 870460.61
B25: Vestland | C25: =E8 -> 857949.8
B26: More og Romsdal | C26: 806157.02
B27: Nordland | C27: 816131.11
B28: Trondelag | C28: =E7 -> 848503.61
B29: Oslo | C29: 921618.73
B30: Ostfold | C30: =E9 -> 940998.15
B31: Rogaland | C31: =E5 -> 910580.94
B32: Telemark | C32: =E12 -> 830742.8
B33: Troms | C33: =E6 -> 808402.78
B34: Vestfold | C34: 830742.8

Sheet per profession and gender
A1: Job title | B1: min | C1: max | D1: average | M1: kjønn | N1: count
A2: {=_xlfn.UNIQUE('data input'!H2:H2683)} -> AI / maskinlæring | B2: =_xlfn.MINIFS('data input'!$K$2:$K$2683,'data input'!$H$2:$H$2683,'per profession and gender'!A2) -> 525000 | C2: =_xlfn.MAXIFS('data input'!$K$2:$K$2683,'data input'!$H$2:$H$2683,'per profession and gender'!A2) -> 1950000 | D2: =AVERAGEIFS('data input'!$K$2:$K$2683,'data input'!$H$2:$H$2683,'per profession and gender'!A2) -> 897413.79 | M2: kvinne | N2: =COUNTIF('data input'!$C:$C,'per profession and gender'!M2) -> 368
A3: annet | B3: =_xlfn.MINIFS('data input'!$K$2:$K$2683,'data input'!$H$2:$H$2683,'per profession and gender'!A3) -> 310000 | C3: =_xlfn.MAXIFS('data input'!$K$2:$K$2683,'data input'!$H$2:$H$2683,'per profession and gender'!A3) -> 2400000 | D3: =AVERAGEIFS('data input'!$K$2:$K$2683,'data input'!$H$2:$H$2683,'per profession and gender'!A3) -> 943600 | M3: mann | N3: =COUNTIF('data input'!$C:$C,'per profession and gender'!M3) -> 2295
A4: app | B4: =_xlfn.MINIFS('data input'!$K$2:$K$2683,'data input'!$H$2:$H$2683,'per profession and gender'!A4) -> 510000 | C4: =_xlfn.MAXIFS('data input'!$K$2:$K$2683,'data input'!$H$2:$H$2683,'per profession and gender'!A4) -> 1750000 | D4: =AVERAGEIFS('data input'!$K$2:$K$2683,'data input'!$H$2:$H$2683,'per profession and gender'!A4) -> 844980.81 | M4: annet / ønsker ikke oppgi | N4: =COUNTIF('data input'!$C:$C,'per profession and gender'!M4) -> 19
A5: arkitektur | B5: =_xlfn.MINIFS('data input'!$K$2:$K$2683,'data input'!$H$2:$H$2683,'per profession and gender'!A5) -> 530000 | C5: =_xlfn.MAXIFS('data input'!$K$2:$K$2683,'data input'!$H$2:$H$2683,'per profession and gender'!A5) -> 2500000 | D5: =AVERAGEIFS('data input'!$K$2:$K$2683,'data input'!$H$2:$H$2683,'per profession and gender'!A5) -> 1135868.2
A6: automatisering | B6: =_xlfn.MINIFS('data input'!$K$2:$K$2683,'data input'!$H$2:$H$2683,'per profession and gender'!A6) -> 350000 | C6: =_xlfn.MAXIFS('data input'!$K$2:$K$2683,'data input'!$H$2:$H$2683,'per profession and gender'!A6) -> 1800000 | D6: =AVERAGEIFS('data input'!$K$2:$K$2683,'data input'!$H$2:$H$2683,'per profession and gender'!A6) -> 915718.75
A7: backend | B7: =_xlfn.MINIFS('data input'!$K$2:$K$2683,'data input'!$H$2:$H$2683,'per profession and gender'!A7) -> 429000 | C7: =_xlfn.MAXIFS('data input'!$K$2:$K$2683,'data input'!$H$2:$H$2683,'per profession and gender'!A7) -> 2500000 | D7: =AVERAGEIFS('data input'!$K$2:$K$2683,'data input'!$H$2:$H$2683,'per profession and gender'!A7) -> 904643.04
A8: data science | B8: =_xlfn.MINIFS('data input'!$K$2:$K$2683,'data input'!$H$2:$H$2683,'per profession and gender'!A8) -> 530000 | C8: =_xlfn.MAXIFS('data input'!$K$2:$K$2683,'data input'!$H$2:$H$2683,'per profession and gender'!A8) -> 1550000 | D8: =AVERAGEIFS('data input'!$K$2:$K$2683,'data input'!$H$2:$H$2683,'per profession and gender'!A8) -> 848137.04
A9: databaser | B9: =_xlfn.MINIFS('data input'!$K$2:$K$2683,'data input'!$H$2:$H$2683,'per profession and gender'!A9) -> 568000 | C9: =_xlfn.MAXIFS('data input'!$K$2:$K$2683,'data input'!$H$2:$H$2683,'per profession and gender'!A9) -> 1300000 | D9: =AVERAGEIFS('data input'!$K$2:$K$2683,'data input'!$H$2:$H$2683,'per profession and gender'!A9) -> 815361.11
A10: devops / drift | B10: =_xlfn.MINIFS('data input'!$K$2:$K$2683,'data input'!$H$2:$H$2683,'per profession and gender'!A10) -> 450000 | C10: =_xlfn.MAXIFS('data input'!$K$2:$K$2683,'data input'!$H$2:$H$2683,'per profession and gender'!A10) -> 2200000 | D10: =AVERAGEIFS('data input'!$K$2:$K$2683,'data input'!$H$2:$H$2683,'per profession and gender'!A10) -> 912234.9
A11: embedded / IOT / maskinvare | B11: =_xlfn.MINIFS('data input'!$K$2:$K$2683,'data input'!$H$2:$H$2683,'per profession and gender'!A11) -> 585000 | C11: =_xlfn.MAXIFS('data input'!$K$2:$K$2683,'data input'!$H$2:$H$2683,'per profession and gender'!A11) -> 2600000 | D11: =AVERAGEIFS('data input'!$K$2:$K$2683,'data input'!$H$2:$H$2683,'per profession and gender'!A11) -> 956107.17
A12: frontend | B12: =_xlfn.MINIFS('data input'!$K$2:$K$2683,'data input'!$H$2:$H$2683,'per profession and gender'!A12) -> 370000 | C12: =_xlfn.MAXIFS('data input'!$K$2:$K$2683,'data input'!$H$2:$H$2683,'per profession and gender'!A12) -> 2200000 | D12: =AVERAGEIFS('data input'!$K$2:$K$2683,'data input'!$H$2:$H$2683,'per profession and gender'!A12) -> 806002.58
A13: fullstack | B13: =_xlfn.MINIFS('data input'!$K$2:$K$2683,'data input'!$H$2:$H$2683,'per profession and gender'!A13) -> 300000 | C13: =_xlfn.MAXIFS('data input'!$K$2:$K$2683,'data input'!$H$2:$H$2683,'per profession and gender'!A13) -> 2700000 | D13: =AVERAGEIFS('data input'!$K$2:$K$2683,'data input'!$H$2:$H$2683,'per profession and gender'!A13) -> 875207.37
A14: ledelse/administrativt | B14: =_xlfn.MINIFS('data input'!$K$2:$K$2683,'data input'!$H$2:$H$2683,'per profession and gender'!A14) -> 500000 | C14: =_xlfn.MAXIFS('data input'!$K$2:$K$2683,'data input'!$H$2:$H$2683,'per profession and gender'!A14) -> 2500000 | D14: =AVERAGEIFS('data input'!$K$2:$K$2683,'data input'!$H$2:$H$2683,'per profession and gender'!A14) -> 1072832.1
A15: programvare | B15: =_xlfn.MINIFS('data input'!$K$2:$K$2683,'data input'!$H$2:$H$2683,'per profession and gender'!A15) -> 520000 | C15: =_xlfn.MAXIFS('data input'!$K$2:$K$2683,'data input'!$H$2:$H$2683,'per profession and gender'!A15) -> 2500000 | D15: =AVERAGEIFS('data input'!$K$2:$K$2683,'data input'!$H$2:$H$2683,'per profession and gender'!A15) -> 917038.36
A16: sikkerhet | B16: =_xlfn.MINIFS('data input'!$K$2:$K$2683,'data input'!$H$2:$H$2683,'per profession and gender'!A16) -> 415000 | C16: =_xlfn.MAXIFS('data input'!$K$2:$K$2683,'data input'!$H$2:$H$2683,'per profession and gender'!A16) -> 2200000 | D16: =AVERAGEIFS('data input'!$K$2:$K$2683,'data input'!$H$2:$H$2683,'per profession and gender'!A16) -> 927034.33
... A18: UX / design | B18: =_xlfn.MINIFS('data input'!$K$2:$K$2683,'data input'!$H$2:$H$2683,'per profession and gender'!A18) -> 570000 | C18: =_xlfn.MAXIFS('data input'!$K$2:$K$2683,'data input'!$H$2:$H$2683,'per profession and gender'!A18) -> 1550000 | D18: =AVERAGEIFS('data input'!$K$2:$K$2683,'data input'!$H$2:$H$2683,'per profession and gender'!A18) -> 797154.55
A25: Job title | B25: kvinne | C25: kvinne | D25: kvinne | E25: mann | F25: mann | G25: mann
B26: min | C26: max | D26: average | E26: min | F26: max | G26: average
A27: {=_xlfn.UNIQUE('data input'!H2:H2683)} -> AI / maskinlæring | B27: =_xlfn.MINIFS('data input'!$K$2:$K$2683,'data input'!$C$2:$C$2683,'per profession and gender'!$C$25,'data input'!$H$2:$H$2683,'per profession and gender'!A27) -> 732000 | C27: =_xlfn.MAXIFS('data input'!$K$2:$K$2683,'data input'!$C$2:$C$2683,'per profession and gender'!$C$25,'data input'!$H$2:$H$2683,'per profession and gender'!A27) -> 1200000 | D27: =AVERAGEIFS('data input'!$K$2:$K$2683,'data input'!$C$2:$C$2683,'per profession and gender'!$C$25,'data input'!$H$2:$H$2683,'per profession and gender'!A27) -> 966000 | E27: =_xlfn.MINIFS('data input'!$K$2:$K$2683,'data input'!$C$2:$C$2683,'per profession and gender'!$F$25,'data input'!$H$2:$H$2683,'per profession and gender'!A27) -> 525000 | F27: =_xlfn.MAXIFS('data input'!$K$2:$K$2683,'data input'!$C$2:$C$2683,'per profession and gender'!$F$25,'data input'!$H$2:$H$2683,'per profession and gender'!A27) -> 1950000 | G27: =AVERAGEIFS('data input'!$K$2:$K$2683,'data input'!$C$2:$C$2683,'per profession and gender'!$F$25,'data input'!$H$2:$H$2683,'per profession and gender'!A27) -> 897807.69
A28: annet | B28: =_xlfn.MINIFS('data input'!$K$2:$K$2683,'data input'!$C$2:$C$2683,'per profession and gender'!$C$25,'data input'!$H$2:$H$2683,'per profession and gender'!A28) -> 850000 | C28: =_xlfn.MAXIFS('data input'!$K$2:$K$2683,'data input'!$C$2:$C$2683,'per profession and gender'!$C$25,'data input'!$H$2:$H$2683,'per profession and gender'!A28) -> 1500000 | D28: =AVERAGEIFS('data input'!$K$2:$K$2683,'data input'!$C$2:$C$2683,'per profession and gender'!$C$25,'data input'!$H$2:$H$2683,'per profession and gender'!A28) -> 1155000 | E28: =_xlfn.MINIFS('data input'!$K$2:$K$2683,'data input'!$C$2:$C$2683,'per profession and gender'!$F$25,'data input'!$H$2:$H$2683,'per profession and gender'!A28) -> 310000 | F28: =_xlfn.MAXIFS('data input'!$K$2:$K$2683,'data input'!$C$2:$C$2683,'per profession and gender'!$F$25,'data input'!$H$2:$H$2683,'per profession and gender'!A28) -> 2400000 | G28: =AVERAGEIFS('data input'!$K$2:$K$2683,'data input'!$C$2:$C$2683,'per profession and gender'!$F$25,'data input'!$H$2:$H$2683,'per profession and gender'!A28) -> 927019.61
A29: app | B29: =_xlfn.MINIFS('data input'!$K$2:$K$2683,'data input'!$C$2:$C$2683,'per profession and gender'!$C$25,'data input'!$H$2:$H$2683,'per profession and gender'!A29) -> 590000 | C29: =_xlfn.MAXIFS('data input'!$K$2:$K$2683,'data input'!$C$2:$C$2683,'per profession and gender'!$C$25,'data input'!$H$2:$H$2683,'per profession and gender'!A29) -> 1115000 | D29: =AVERAGEIFS('data input'!$K$2:$K$2683,'data input'!$C$2:$C$2683,'per profession and gender'!$C$25,'data input'!$H$2:$H$2683,'per profession and gender'!A29) -> 784954.53 | E29: =_xlfn.MINIFS('data input'!$K$2:$K$2683,'data input'!$C$2:$C$2683,'per profession and gender'!$F$25,'data input'!$H$2:$H$2683,'per profession and gender'!A29) -> 510000 | F29: =_xlfn.MAXIFS('data input'!$K$2:$K$2683,'data input'!$C$2:$C$2683,'per profession and gender'!$F$25,'data input'!$H$2:$H$2683,'per profession and gender'!A29) -> 1750000 | G29: =AVERAGEIFS('data input'!$K$2:$K$2683,'data input'!$C$2:$C$2683,'per profession and gender'!$F$25,'data input'!$H$2:$H$2683,'per profession and gender'!A29) -> 866219.64
A30: arkitektur | B30: =_xlfn.MINIFS('data input'!$K$2:$K$2683,'data input'!$C$2:$C$2683,'per profession and gender'!$C$25,'data input'!$H$2:$H$2683,'per profession and gender'!A30) -> 680000 | C30: =_xlfn.MAXIFS('data input'!$K$2:$K$2683,'data input'!$C$2:$C$2683,'per profession and gender'!$C$25,'data input'!$H$2:$H$2683,'per profession and gender'!A30) -> 1240000 | D30: =AVERAGEIFS('data input'!$K$2:$K$2683,'data input'!$C$2:$C$2683,'per profession and gender'!$C$25,'data input'!$H$2:$H$2683,'per profession and gender'!A30) -> 981000 | E30: =_xlfn.MINIFS('data input'!$K$2:$K$2683,'data input'!$C$2:$C$2683,'per profession and gender'!$F$25,'data input'!$H$2:$H$2683,'per profession and gender'!A30) -> 530000 | F30: =_xlfn.MAXIFS('data input'!$K$2:$K$2683,'data input'!$C$2:$C$2683,'per profession and gender'!$F$25,'data input'!$H$2:$H$2683,'per profession and gender'!A30) -> 2500000 | G30: =AVERAGEIFS('data input'!$K$2:$K$2683,'data input'!$C$2:$C$2683,'per profession and gender'!$F$25,'data input'!$H$2:$H$2683,'per profession and gender'!A30) -> 1150921.8
A31: automatisering | B31: =_xlfn.MINIFS('data input'!$K$2:$K$2683,'data input'!$C$2:$C$2683,'per profession and gender'!$C$25,'data input'!$H$2:$H$2683,'per profession and gender'!A31) -> 568000 | C31: =_xlfn.MAXIFS('data input'!$K$2:$K$2683,'data input'!$C$2:$C$2683,'per profession and gender'!$C$25,'data input'!$H$2:$H$2683,'per profession and gender'!A31) -> 1800000 | D31: =AVERAGEIFS('data input'!$K$2:$K$2683,'data input'!$C$2:$C$2683,'per profession and gender'!$C$25,'data input'!$H$2:$H$2683,'per profession and gender'!A31) -> 888857.14 | E31: =_xlfn.MINIFS('data input'!$K$2:$K$2683,'data input'!$C$2:$C$2683,'per profession and gender'!$F$25,'data input'!$H$2:$H$2683,'per profession and gender'!A31) -> 350000 | F31: =_xlfn.MAXIFS('data input'!$K$2:$K$2683,'data input'!$C$2:$C$2683,'per profession and gender'!$F$25,'data input'!$H$2:$H$2683,'per profession and gender'!A31) -> 1800000 | G31: =AVERAGEIFS('data input'!$K$2:$K$2683,'data input'!$C$2:$C$2683,'per profession and gender'!$F$25,'data input'!$H$2:$H$2683,'per profession and gender'!A31) -> 923240
A32: backend | B32: =_xlfn.MINIFS('data input'!$K$2:$K$2683,'data input'!$C$2:$C$2683,'per profession and gender'!$C$25,'data input'!$H$2:$H$2683,'per profession and gender'!A32) -> 437000 | C32: =_xlfn.MAXIFS('data input'!$K$2:$K$2683,'data input'!$C$2:$C$2683,'per profession and gender'!$C$25,'data input'!$H$2:$H$2683,'per profession and gender'!A32) -> 1200000 | D32: =AVERAGEIFS('data input'!$K$2:$K$2683,'data input'!$C$2:$C$2683,'per profession and gender'!$C$25,'data input'!$H$2:$H$2683,'per profession and gender'!A32) -> 852112.24 | E32: =_xlfn.MINIFS('data input'!$K$2:$K$2683,'data input'!$C$2:$C$2683,'per profession and gender'!$F$25,'data input'!$H$2:$H$2683,'per profession and gender'!A32) -> 429000 | F32: =_xlfn.MAXIFS('data input'!$K$2:$K$2683,'data input'!$C$2:$C$2683,'per profession and gender'!$F$25,'data input'!$H$2:$H$2683,'per profession and gender'!A32) -> 2500000 | G32: =AVERAGEIFS('data input'!$K$2:$K$2683,'data input'!$C$2:$C$2683,'per profession and gender'!$F$25,'data input'!$H$2:$H$2683,'per profession and gender'!A32) -> 910526.12
A33: data science | B33: =_xlfn.MINIFS('data input'!$K$2:$K$2683,'data input'!$C$2:$C$2683,'per profession and gender'!$C$25,'data input'!$H$2:$H$2683,'per profession and gender'!A33) -> 530000 | C33: =_xlfn.MAXIFS('data input'!$K$2:$K$2683,'data input'!$C$2:$C$2683,'per profession and gender'!$C$25,'data input'!$H$2:$H$2683,'per profession and gender'!A33) -> 780000 | D33: =AVERAGEIFS('data input'!$K$2:$K$2683,'data input'!$C$2:$C$2683,'per profession and gender'!$C$25,'data input'!$H$2:$H$2683,'per profession and gender'!A33) -> 660833.33 | E33: =_xlfn.MINIFS('data input'!$K$2:$K$2683,'data input'!$C$2:$C$2683,'per profession and gender'!$F$25,'data input'!$H$2:$H$2683,'per profession and gender'!A33) -> 560000 | F33: =_xlfn.MAXIFS('data input'!$K$2:$K$2683,'data input'!$C$2:$C$2683,'per profession and gender'!$F$25,'data input'!$H$2:$H$2683,'per profession and gender'!A33) -> 1550000 | G33: =AVERAGEIFS('data input'!$K$2:$K$2683,'data input'!$C$2:$C$2683,'per profession and gender'!$F$25,'data input'!$H$2:$H$2683,'per profession and gender'!A33) -> 871550
A34: databaser | B34: =_xlfn.MINIFS('data input'!$K$2:$K$2683,'data input'!$C$2:$C$2683,'per profession and gender'!$C$25,'data input'!$H$2:$H$2683,'per profession and gender'!A34) -> 595000 | C34: =_xlfn.MAXIFS('data input'!$K$2:$K$2683,'data input'!$C$2:$C$2683,'per profession and gender'!$C$25,'data input'!$H$2:$H$2683,'per profession and gender'!A34) -> 1200000 | D34: =AVERAGEIFS('data input'!$K$2:$K$2683,'data input'!$C$2:$C$2683,'per profession and gender'!$C$25,'data input'!$H$2:$H$2683,'per profession and gender'!A34) -> 848461.54 | E34: =_xlfn.MINIFS('data input'!$K$2:$K$2683,'data input'!$C$2:$C$2683,'per profession and gender'!$F$25,'data input'!$H$2:$H$2683,'per profession and gender'!A34) -> 568000 | F34: =_xlfn.MAXIFS('data input'!$K$2:$K$2683,'data input'!$C$2:$C$2683,'per profession and gender'!$F$25,'data input'!$H$2:$H$2683,'per profession and gender'!A34) -> 1300000 | G34: =AVERAGEIFS('data input'!$K$2:$K$2683,'data input'!$C$2:$C$2683,'per profession and gender'!$F$25,'data input'!$H$2:$H$2683,'per profession and gender'!A34) -> 796652.17
A35: devops / drift | B35: =_xlfn.MINIFS('data input'!$K$2:$K$2683,'data input'!$C$2:$C$2683,'per profession and gender'!$C$25,'data input'!$H$2:$H$2683,'per profession and gender'!A35) -> 480000 | C35: =_xlfn.MAXIFS('data input'!$K$2:$K$2683,'data input'!$C$2:$C$2683,'per profession and gender'!$C$25,'data input'!$H$2:$H$2683,'per profession and gender'!A35) -> 900000 | D35: =AVERAGEIFS('data input'!$K$2:$K$2683,'data input'!$C$2:$C$2683,'per profession and gender'!$C$25,'data input'!$H$2:$H$2683,'per profession and gender'!A35) -> 679166.67 | E35: =_xlfn.MINIFS('data input'!$K$2:$K$2683,'data input'!$C$2:$C$2683,'per profession and gender'!$F$25,'data input'!$H$2:$H$2683,'per profession and gender'!A35) -> 450000 | F35: =_xlfn.MAXIFS('data input'!$K$2:$K$2683,'data input'!$C$2:$C$2683,'per profession and gender'!$F$25,'data input'!$H$2:$H$2683,'per profession and gender'!A35) -> 2200000 | G35: =AVERAGEIFS('data input'!$K$2:$K$2683,'data input'!$C$2:$C$2683,'per profession and gender'!$F$25,'data input'!$H$2:$H$2683,'per profession and gender'!A35) -> 923159.98
A36: embedded / IOT / maskinvare | B36: =_xlfn.MINIFS('data input'!$K$2:$K$2683,'data input'!$C$2:$C$2683,'per profession and gender'!$C$25,'data input'!$H$2:$H$2683,'per profession and gender'!A36) -> 585000 | C36: =_xlfn.MAXIFS('data input'!$K$2:$K$2683,'data input'!$C$2:$C$2683,'per profession and gender'!$C$25,'data input'!$H$2:$H$2683,'per profession and gender'!A36) -> 950000 | D36: =AVERAGEIFS('data input'!$K$2:$K$2683,'data input'!$C$2:$C$2683,'per profession and gender'!$C$25,'data input'!$H$2:$H$2683,'per profession and gender'!A36) -> 767500 | E36: =_xlfn.MINIFS('data input'!$K$2:$K$2683,'data input'!$C$2:$C$2683,'per profession and gender'!$F$25,'data input'!$H$2:$H$2683,'per profession and gender'!A36) -> 630000 | F36: =_xlfn.MAXIFS('data input'!$K$2:$K$2683,'data input'!$C$2:$C$2683,'per profession and gender'!$F$25,'data input'!$H$2:$H$2683,'per profession and gender'!A36) -> 2600000 | G36: =AVERAGEIFS('data input'!$K$2:$K$2683,'data input'!$C$2:$C$2683,'per profession and gender'!$F$25,'data input'!$H$2:$H$2683,'per profession and gender'!A36) -> 988273.25
A37: frontend | B37: =_xlfn.MINIFS('data input'!$K$2:$K$2683,'data input'!$C$2:$C$2683,'per profession and gender'!$C$25,'data input'!$H$2:$H$2683,'per profession and gender'!A37) -> 490000 | C37: =_xlfn.MAXIFS('data input'!$K$2:$K$2683,'data input'!$C$2:$C$2683,'per profession and gender'!$C$25,'data input'!$H$2:$H$2683,'per profession and gender'!A37) -> 1200000 | D37: =AVERAGEIFS('data input'!$K$2:$K$2683,'data input'!$C$2:$C$2683,'per profession and gender'!$C$25,'data input'!$H$2:$H$2683,'per profession and gender'!A37) -> 742819.91 | E37: =_xlfn.MINIFS('data input'!$K$2:$K$2683,'data input'!$C$2:$C$2683,'per profession and gender'!$F$25,'data input'!$H$2:$H$2683,'per profession and gender'!A37) -> 370000 | F37: =_xlfn.MAXIFS('data input'!$K$2:$K$2683,'data input'!$C$2:$C$2683,'per profession and gender'!$F$25,'data input'!$H$2:$H$2683,'per profession and gender'!A37) -> 2200000 | G37: =AVERAGEIFS('data input'!$K$2:$K$2683,'data input'!$C$2:$C$2683,'per profession and gender'!$F$25,'data input'!$H$2:$H$2683,'per profession and gender'!A37) -> 825733.32
A38: fullstack | B38: =_xlfn.MINIFS('data input'!$K$2:$K$2683,'data input'!$C$2:$C$2683,'per profession and gender'!$C$25,'data input'!$H$2:$H$2683,'per profession and gender'!A38) -> 450000 | C38: =_xlfn.MAXIFS('data input'!$K$2:$K$2683,'data input'!$C$2:$C$2683,'per profession and gender'!$C$25,'data input'!$H$2:$H$2683,'per profession and gender'!A38) -> 1400000 | D38: =AVERAGEIFS('data input'!$K$2:$K$2683,'data input'!$C$2:$C$2683,'per profession and gender'!$C$25,'data input'!$H$2:$H$2683,'per profession and gender'!A38) -> 793761.63 | E38: =_xlfn.MINIFS('data input'!$K$2:$K$2683,'data input'!$C$2:$C$2683,'per profession and gender'!$F$25,'data input'!$H$2:$H$2683,'per profession and gender'!A38) -> 300000 | F38: =_xlfn.MAXIFS('data input'!$K$2:$K$2683,'data input'!$C$2:$C$2683,'per profession and gender'!$F$25,'data input'!$H$2:$H$2683,'per profession and gender'!A38) -> 2700000 | G38: =AVERAGEIFS('data input'!$K$2:$K$2683,'data input'!$C$2:$C$2683,'per profession and gender'!$F$25,'data input'!$H$2:$H$2683,'per profession and gender'!A38) -> 883327.13
A39: ledelse/administrativt | B39: =_xlfn.MINIFS('data input'!$K$2:$K$2683,'data input'!$C$2:$C$2683,'per profession and gender'!$C$25,'data input'!$H$2:$H$2683,'per profession and gender'!A39) -> 627000 | C39: =_xlfn.MAXIFS('data input'!$K$2:$K$2683,'data input'!$C$2:$C$2683,'per profession and gender'!$C$25,'data input'!$H$2:$H$2683,'per profession and gender'!A39) -> 1364000 | D39: =AVERAGEIFS('data input'!$K$2:$K$2683,'data input'!$C$2:$C$2683,'per profession and gender'!$C$25,'data input'!$H$2:$H$2683,'per profession and gender'!A39) -> 972733.33 | E39: =_xlfn.MINIFS('data input'!$K$2:$K$2683,'data input'!$C$2:$C$2683,'per profession and gender'!$F$25,'data input'!$H$2:$H$2683,'per profession and gender'!A39) -> 500000 | F39: =_xlfn.MAXIFS('data input'!$K$2:$K$2683,'data input'!$C$2:$C$2683,'per profession and gender'!$F$25,'data input'!$H$2:$H$2683,'per profession and gender'!A39) -> 2500000 | G39: =AVERAGEIFS('data input'!$K$2:$K$2683,'data input'!$C$2:$C$2683,'per profession and gender'!$F$25,'data input'!$H$2:$H$2683,'per profession and gender'!A39) -> 1100830.4
... A43: UX / design | B43: =_xlfn.MINIFS('data input'!$K$2:$K$2683,'data input'!$C$2:$C$2683,'per profession and gender'!$C$25,'data input'!$H$2:$H$2683,'per profession and gender'!A43) -> 570000 | C43: =_xlfn.MAXIFS('data input'!$K$2:$K$2683,'data input'!$C$2:$C$2683,'per profession and gender'!$C$25,'data input'!$H$2:$H$2683,'per profession and gender'!A43) -> 920000 | D43: =AVERAGEIFS('data input'!$K$2:$K$2683,'data input'!$C$2:$C$2683,'per profession and gender'!$C$25,'data input'!$H$2:$H$2683,'per profession and gender'!A43) -> 711078.12 | E43: =_xlfn.MINIFS('data input'!$K$2:$K$2683,'data input'!$C$2:$C$2683,'per profession and gender'!$F$25,'data input'!$H$2:$H$2683,'per profession and gender'!A43) -> 600000 | F43: =_xlfn.MAXIFS('data input'!$K$2:$K$2683,'data input'!$C$2:$C$2683,'per profession and gender'!$F$25,'data input'!$H$2:$H$2683,'per profession and gender'!A43) -> 1550000 | G43: =AVERAGEIFS('data input'!$K$2:$K$2683,'data input'!$C$2:$C$2683,'per profession and gender'!$F$25,'data input'!$H$2:$H$2683,'per profession and gender'!A43) -> 945666.67
B45: =AVERAGE(B27:B43) -> 587882.35 | C45: =AVERAGE(C27:C43) -> 1191294.1 | D45: =AVERAGE(D27:D43) -> 837681.95 | E45: =AVERAGE(E27:E43) -> 475294.12 | F45: =AVERAGE(F27:F43) -> 2129411.8 | G45: =AVERAGE(G27:G43) -> 932763.51
A47: Job title | C47: mann
B48: min | C48: max | D48: average
A49: {=_xlfn.UNIQUE('data input'!H24:H2705)} -> AI / maskinlæring | B49: =_xlfn.MINIFS('data input'!$K$2:$K$2683,'data input'!$C$2:$C$2683,'per profession and gender'!$C$47,'data input'!$H$2:$H$2683,'per profession and gender'!A49) -> 525000 | C49: =_xlfn.MAXIFS('data input'!$K$2:$K$2683,'data input'!$C$2:$C$2683,'per profession and gender'!$C$47,'data input'!$H$2:$H$2683,'per profession and gender'!A49) -> 1950000 | D49: =AVERAGEIFS('data input'!$K$2:$K$2683,'data input'!$C$2:$C$2683,'per profession and gender'!$C$47,'data input'!$H$2:$H$2683,'per profession and gender'!A49) -> 897807.69
A50: annet | B50: =_xlfn.MINIFS('data input'!$K$2:$K$2683,'data input'!$C$2:$C$2683,'per profession and gender'!$C$47,'data input'!$H$2:$H$2683,'per profession and gender'!A50) -> 310000 | C50: =_xlfn.MAXIFS('data input'!$K$2:$K$2683,'data input'!$C$2:$C$2683,'per profession and gender'!$C$47,'data input'!$H$2:$H$2683,'per profession and gender'!A50) -> 2400000 | D50: =AVERAGEIFS('data input'!$K$2:$K$2683,'data input'!$C$2:$C$2683,'per profession and gender'!$C$47,'data input'!$H$2:$H$2683,'per profession and gender'!A50) -> 927019.61
A51: app | B51: =_xlfn.MINIFS('data input'!$K$2:$K$2683,'data input'!$C$2:$C$2683,'per profession and gender'!$C$47,'data input'!$H$2:$H$2683,'per profession and gender'!A51) -> 510000 | C51: =_xlfn.MAXIFS('data input'!$K$2:$K$2683,'data input'!$C$2:$C$2683,'per profession and gender'!$C$47,'data input'!$H$2:$H$2683,'per profession and gender'!A51) -> 1750000 | D51: =AVERAGEIFS('data input'!$K$2:$K$2683,'data input'!$C$2:$C$2683,'per profession and gender'!$C$47,'data input'!$H$2:$H$2683,'per profession and gender'!A51) -> 866219.64
A52: arkitektur | B52: =_xlfn.MINIFS('data input'!$K$2:$K$2683,'data input'!$C$2:$C$2683,'per profession and gender'!$C$47,'data input'!$H$2:$H$2683,'per profession and gender'!A52) -> 530000 | C52: =_xlfn.MAXIFS('data input'!$K$2:$K$2683,'data input'!$C$2:$C$2683,'per profession and gender'!$C$47,'data input'!$H$2:$H$2683,'per profession and gender'!A52) -> 2500000 | D52: =AVERAGEIFS('data input'!$K$2:$K$2683,'data input'!$C$2:$C$2683,'per profession and gender'!$C$47,'data input'!$H$2:$H$2683,'per profession and gender'!A52) -> 1150921.8
...

Sheet Developers salary
A1: Developers salary in Norway, 2024
D3: Job Title | J3: Arbeidssted | L3: Experience
D4: fullstack | J4: Oslo | L4: 9 - 14

Sheet data validation
A1: job_title_short | B1: n of job positions | E1: job_title_short_sorted | F1: n of posit | I1: work places | J1: work places sorted | M1: arbeidssituasjon | O1: experience buckets | P1: help to sort | Q1: experience buckets_sorted
A2: {=_xlfn.UNIQUE('data input'!H2:H2683)} -> AI / maskinlæring | B2: =COUNTIF('data input'!H2:H2683,A2) -> 29 | E2: {=_xlfn._xlws.SORT(A2:B18,2, -1)} -> fullstack | F2: 893 | I2: {=_xlfn.UNIQUE('data input'!F2:F2683)} -> Agder | J2: {=_xlfn._xlws.SORT(_xlfn.ANCHORARRAY(I2))} -> Agder | M2: {=_xlfn.UNIQUE('data input'!G2:G2683)} -> "in-house: privat sektor" | O2: {=_xlfn.UNIQUE('data input'!L2:L2683)} -> 5 - 8 | P2: 1 | Q2: {=_xlfn.SORTBY(_xlfn.ANCHORARRAY(O2),P2:P5,-1)} -> 15 +
A3: annet | B3: =COUNTIF('data input'!H3:H2684,A3) -> 55 | E3: backend | F3: 536 | I3: Nordland | J3: Innlandet | M3: "in-house: offentlig/kommunal sektor" | O3: 0 - 4 | P3: 0 | Q3: 9 - 14
A4: app | B4: =COUNTIF('data input'!H4:H2685,A4) -> 72 | E4: frontend | F4: 334 | I4: Oslo | J4: Møre og Romsdal | M4: konsulent | O4: 15 + | P4: 3 | Q4: 5 - 8
A5: arkitektur | B5: =COUNTIF('data input'!H5:H2686,A5) -> 113 | E5: ledelse/administrativt | F5: 148 | I5: Rogaland | J5: Nordland | M5: frilans / selvstendig næringsdrivende | O5: 9 - 14 | P5: 2 | Q5: 0 - 4
A6: automatisering | B6: =COUNTIF('data input'!H6:H2687,A6) -> 32 | E6: devops / drift | F6: 134 | I6: Troms og Finnmark | J6: Oslo
A7: backend | B7: =COUNTIF('data input'!H7:H2688,A7) -> 536 | E7: arkitektur | F7: 113 | I7: Trøndelag | J7: Rogaland
A8: data science | B8: =COUNTIF('data input'!H8:H2689,A8) -> 54 | E8: app | F8: 72 | I8: Vestland | J8: Troms og Finnmark
A9: databaser | B9: =COUNTIF('data input'!H9:H2690,A9) -> 36 | E9: programvare | F9: 72 | I9: Viken | J9: Trøndelag
A10: devops / drift | B10: =COUNTIF('data input'!H10:H2691,A10) -> 134 | E10: sikkerhet | F10: 67 | I10: Innlandet | J10: utlandet
A11: embedded / IOT / maskinvare | B11: =COUNTIF('data input'!H11:H2692,A11) -> 23 | E11: annet | F11: 55 | I11: utlandet | J11: Vestfold og Telemark
A12: frontend | B12: =COUNTIF('data input'!H12:H2693,A12) -> 334 | E12: UX / design | F12: 55 | I12: Vestfold og Telemark | J12: Vestland
A13: fullstack | B13: =COUNTIF('data input'!H13:H2694,A13) -> 893 | E13: data science | F13: 54 | I13: Møre og Romsdal | J13: Viken
A14: ledelse/administrativt | B14: =COUNTIF('data input'!H14:H2695,A14) -> 148 | E14: databaser | F14: 36
A15: programvare | B15: =COUNTIF('data input'!H15:H2696,A15) -> 72 | E15: automatisering | F15: 32
A16: sikkerhet | B16: =COUNTIF('data input'!H16:H2697,A16) -> 67 | E16: AI / maskinlæring | F16: 29
A17: testing | B17: =COUNTIF('data input'!H17:H2698,A17) -> 29 | E17: testing | F17: 29
A18: UX / design | B18: =COUNTIF('data input'!H18:H2699,A18) -> 55 | E18: embedded / IOT / maskinvare | F18: 23
A22: Total: | B22: =SUM(B2:B18) -> 2682

Sheet title
A1: {='data validation'!E1:E18} -> job_title_short_sorted | B1: median salary | E1: Title sorted | F1: median salary | H1: values for plotting
A2: fullstack | B2: {=MEDIAN( IF( ('data input'!$H$2:$H$2683= A2) * ('data input'!$F$2:$F$2683= fylke) * ('data input'!$K$2:$K$2683 <> 0) * ('data input'!$L$2:$L$2683= experience), ('data input'!$K$2:$K$2683)))} -> 1075000 | E2: {=_xlfn._xlws.SORT(A2:B18,2,-1)} -> sikkerhet | F2: 1350000 | H2: =IF(E2<>title,F2,NA()) -> 1350000 | I2: =IF(E2=title,F2,NA()) -> #N/A
A3: backend | B3: {=MEDIAN( IF( ('data input'!$H$2:$H$2683= A3) * ('data input'!$F$2:$F$2683= fylke) * ('data input'!$K$2:$K$2683 <> 0) * ('data input'!$L$2:$L$2683= experience), ('data input'!$K$2:$K$2683)))} -> 1052000 | E3: arkitektur | F3: 1300000 | H3: =IF(E3<>title,F3,NA()) -> 1300000 | I3: =IF(E3=title,F3,NA()) -> #N/A
A4: frontend | B4: {=MEDIAN( IF( ('data input'!$H$2:$H$2683= A4) * ('data input'!$F$2:$F$2683= fylke) * ('data input'!$K$2:$K$2683 <> 0) * ('data input'!$L$2:$L$2683= experience), ('data input'!$K$2:$K$2683)))} -> 950000 | E4: testing | F4: 1100000 | H4: =IF(E4<>title,F4,NA()) -> 1100000 | I4: =IF(E4=title,F4,NA()) -> #N/A
A5: ledelse/administrativt | B5: {=MEDIAN( IF( ('data input'!$H$2:$H$2683= A5) * ('data input'!$F$2:$F$2683= fylke) * ('data input'!$K$2:$K$2683 <> 0) * ('data input'!$L$2:$L$2683= experience), ('data input'!$K$2:$K$2683)))} -> 1085371 | E5: ledelse/administrativt | F5: 1085371 | H5: =IF(E5<>title,F5,NA()) -> 1085371 | I5: =IF(E5=title,F5,NA()) -> #N/A
A6: devops / drift | B6: {=MEDIAN( IF( ('data input'!$H$2:$H$2683= A6) * ('data input'!$F$2:$F$2683= fylke) * ('data input'!$K$2:$K$2683 <> 0) * ('data input'!$L$2:$L$2683= experience), ('data input'!$K$2:$K$2683)))} -> 1000000 | E6: fullstack | F6: 1075000 | H6: =IF(E6<>title,F6,NA()) -> #N/A | I6: =IF(E6=title,F6,NA()) -> 1075000
A7: arkitektur | B7: {=MEDIAN( IF( ('data input'!$H$2:$H$2683= A7) * ('data input'!$F$2:$F$2683= fylke) * ('data input'!$K$2:$K$2683 <> 0) * ('data input'!$L$2:$L$2683= experience), ('data input'!$K$2:$K$2683)))} -> 1300000 | E7: backend | F7: 1052000 | H7: =IF(E7<>title,F7,NA()) -> 1052000 | I7: =IF(E7=title,F7,NA()) -> #N/A
A8: app | B8: {=MEDIAN( IF( ('data input'!$H$2:$H$2683= A8) * ('data input'!$F$2:$F$2683= fylke) * ('data input'!$K$2:$K$2683 <> 0) * ('data input'!$L$2:$L$2683= experience), ('data input'!$K$2:$K$2683)))} -> 985000 | E8: data science | F8: 1045000 | H8: =IF(E8<>title,F8,NA()) -> 1045000 | I8: =IF(E8=title,F8,NA()) -> #N/A
A9: programvare | B9: {=MEDIAN( IF( ('data input'!$H$2:$H$2683= A9) * ('data input'!$F$2:$F$2683= fylke) * ('data input'!$K$2:$K$2683 <> 0) * ('data input'!$L$2:$L$2683= experience), ('data input'!$K$2:$K$2683)))} -> 980000 | E9: automatisering | F9: 1037000 | H9: =IF(E9<>title,F9,NA()) -> 1037000 | I9: =IF(E9=title,F9,NA()) -> #N/A
A10: sikkerhet | B10: {=MEDIAN( IF( ('data input'!$H$2:$H$2683= A10) * ('data input'!$F$2:$F$2683= fylke) * ('data input'!$K$2:$K$2683 <> 0) * ('data input'!$L$2:$L$2683= experience), ('data input'!$K$2:$K$2683)))} -> 1350000 | E10: devops / drift | F10: 1000000 | H10: =IF(E10<>title,F10,NA()) -> 1000000 | I10: =IF(E10=title,F10,NA()) -> #N/A
A11: annet | B11: {=MEDIAN( IF( ('data input'!$H$2:$H$2683= A11) * ('data input'!$F$2:$F$2683= fylke) * ('data input'!$K$2:$K$2683 <> 0) * ('data input'!$L$2:$L$2683= experience), ('data input'!$K$2:$K$2683)))} -> 960000 | E11: embedded / IOT / maskinvare | F11: 987500 | H11: =IF(E11<>title,F11,NA()) -> 987500 | I11: =IF(E11=title,F11,NA()) -> #N/A
A12: UX / design | B12: {=MEDIAN( IF( ('data input'!$H$2:$H$2683= A12) * ('data input'!$F$2:$F$2683= fylke) * ('data input'!$K$2:$K$2683 <> 0) * ('data input'!$L$2:$L$2683= experience), ('data input'!$K$2:$K$2683)))} -> 880000 | E12: app | F12: 985000 | H12: =IF(E12<>title,F12,NA()) -> 985000 | I12: =IF(E12=title,F12,NA()) -> #N/A
A13: data science | B13: {=MEDIAN( IF( ('data input'!$H$2:$H$2683= A13) * ('data input'!$F$2:$F$2683= fylke) * ('data input'!$K$2:$K$2683 <> 0) * ('data input'!$L$2:$L$2683= experience), ('data input'!$K$2:$K$2683)))} -> 1045000 | E13: programvare | F13: 980000 | H13: =IF(E13<>title,F13,NA()) -> 980000 | I13: =IF(E13=title,F13,NA()) -> #N/A
A14: databaser | B14: {=MEDIAN( IF( ('data input'!$H$2:$H$2683= A14) * ('data input'!$F$2:$F$2683= fylke) * ('data input'!$K$2:$K$2683 <> 0) * ('data input'!$L$2:$L$2683= experience), ('data input'!$K$2:$K$2683)))} -> 922500 | E14: AI / maskinlæring | F14: 980000 | H14: =IF(E14<>title,F14,NA()) -> 980000 | I14: =IF(E14=title,F14,NA()) -> #N/A
... A18: embedded / IOT / maskinvare | B18: {=MEDIAN( IF( ('data input'!$H$2:$H$2683= A18) * ('data input'!$F$2:$F$2683= fylke) * ('data input'!$K$2:$K$2683 <> 0) * ('data input'!$L$2:$L$2683= experience), ('data input'!$K$2:$K$2683)))} -> 987500 | E18: UX / design | F18: 880000 | H18: =IF(E18<>title,F18,NA()) -> 880000 | I18: =IF(E18=title,F18,NA()) -> #N/A
A23: median salary based on title
A24: =_xlfn.XLOOKUP(title,title!E2:E18,title!F2:F18) -> 1075000

Sheet fylke
A1: Fylke | B1: med_salary | D1: Nye fylke(etter 2024)
A2: {=_xlfn.ANCHORARRAY('data validation'!I2)} -> Agder | B2: {=MEDIAN( IF( ('data input'!$F$2:$F$2683= A2) * ('data input'!$K$2:$K$2683 <> 0) * ('data input'!$H$2:$H$2683 = title)* ('data input'!$L$2:$L$2683= experience), 'data input'!$K$2:$K$2683))} -> 895000 | D2: =A2 -> Agder | E2: =B2 -> 895000
A3: Nordland | B3: {=MEDIAN( IF( ('data input'!$F$2:$F$2683= A3) * ('data input'!$K$2:$K$2683 <> 0) * ('data input'!$H$2:$H$2683 = title)* ('data input'!$L$2:$L$2683= experience), 'data input'!$K$2:$K$2683))} -> 1000000 | D3: =A3 -> Nordland | E3: =B3 -> 1000000
A4: Oslo | B4: {=MEDIAN( IF( ('data input'!$F$2:$F$2683= A4) * ('data input'!$K$2:$K$2683 <> 0) * ('data input'!$H$2:$H$2683 = title)* ('data input'!$L$2:$L$2683= experience), 'data input'!$K$2:$K$2683))} -> 1075000 | D4: =A4 -> Oslo | E4: =B4 -> 1075000
A5: Rogaland | B5: {=MEDIAN( IF( ('data input'!$F$2:$F$2683= A5) * ('data input'!$K$2:$K$2683 <> 0) * ('data input'!$H$2:$H$2683 = title)* ('data input'!$L$2:$L$2683= experience), 'data input'!$K$2:$K$2683))} -> 1035000 | D5: =A5 -> Rogaland | E5: =B5 -> 1035000
A6: Troms og Finnmark | B6: {=MEDIAN( IF( ('data input'!$F$2:$F$2683= A6) * ('data input'!$K$2:$K$2683 <> 0) * ('data input'!$H$2:$H$2683 = title)* ('data input'!$L$2:$L$2683= experience), 'data input'!$K$2:$K$2683))} -> 850000 | D6: Trondelag | E6: =B7 -> 903000
A7: Trøndelag | B7: {=MEDIAN( IF( ('data input'!$F$2:$F$2683= A7) * ('data input'!$K$2:$K$2683 <> 0) * ('data input'!$H$2:$H$2683 = title)* ('data input'!$L$2:$L$2683= experience), 'data input'!$K$2:$K$2683))} -> 903000 | D7: =A8 -> Vestland | E7: =B8 -> 980500
A8: Vestland | B8: {=MEDIAN( IF( ('data input'!$F$2:$F$2683= A8) * ('data input'!$K$2:$K$2683 <> 0) * ('data input'!$H$2:$H$2683 = title)* ('data input'!$L$2:$L$2683= experience), 'data input'!$K$2:$K$2683))} -> 980500 | D8: =A10 -> Innlandet | E8: =B10 -> 900000
A9: Viken | B9: {=MEDIAN( IF( ('data input'!$F$2:$F$2683= A9) * ('data input'!$K$2:$K$2683 <> 0) * ('data input'!$H$2:$H$2683 = title)* ('data input'!$L$2:$L$2683= experience), 'data input'!$K$2:$K$2683))} -> 1063000 | D9: More og Romsdal | E9: =B13 -> 845000
A10: Innlandet | B10: {=MEDIAN( IF( ('data input'!$F$2:$F$2683= A10) * ('data input'!$K$2:$K$2683 <> 0) * ('data input'!$H$2:$H$2683 = title)* ('data input'!$L$2:$L$2683= experience), 'data input'!$K$2:$K$2683))} -> 900000 | D10: =IF(ISNUMBER(B12), "Vestfold") -> Vestfold | E10: =IF(ISNUMBER(B12),B12) -> 752000
A11: utlandet | B11: {=MEDIAN( IF( ('data input'!$F$2:$F$2683= A11) * ('data input'!$K$2:$K$2683 <> 0) * ('data input'!$H$2:$H$2683 = title)* ('data input'!$L$2:$L$2683= experience), 'data input'!$K$2:$K$2683))} -> 884000 | D11: =IF(ISNUMBER(B12), "Telemark") -> Telemark | E11: =IF(ISNUMBER(B12),B12) -> 752000
A12: Vestfold og Telemark | B12: {=MEDIAN( IF( ('data input'!$F$2:$F$2683= A12) * ('data input'!$K$2:$K$2683 <> 0) * ('data input'!$H$2:$H$2683 = title)* ('data input'!$L$2:$L$2683= experience), 'data input'!$K$2:$K$2683))} -> 752000 | D12: =IF(ISNUMBER(B6), "Troms") -> Troms | E12: =IF(ISNUMBER(B6),B6) -> 850000
A13: Møre og Romsdal | B13: {=MEDIAN( IF( ('data input'!$F$2:$F$2683= A13) * ('data input'!$K$2:$K$2683 <> 0) * ('data input'!$H$2:$H$2683 = title)* ('data input'!$L$2:$L$2683= experience), 'data input'!$K$2:$K$2683))} -> 845000 | D13: =IF(ISNUMBER(B6), "Finnmark") -> Finnmark | E13: =IF(ISNUMBER(B6),B6) -> 850000
D14: =IF(ISNUMBER(B9), "Akershus") -> Akershus | E14: =IF(ISNUMBER(B9), B9) -> 1063000
D15: =IF(ISNUMBER(B9), "Buskerud") -> Buskerud | E15: =IF(ISNUMBER(B9), B9) -> 1063000
D16: =IF(ISNUMBER(B9), "Ostfold") -> Ostfold | E16: =IF(ISNUMBER(B9), B9) -> 1063000
D17: =A11 -> utlandet | E17: =B11 -> 884000

Sheet experience
A1: {='data validation'!Q1:Q5} -> experience buckets_sorted | B1: median salary per fylke and job type | F1: sorted by salary | I1: values for plotting
A2: 15 + | B2: {=MEDIAN( IF( ('data input'!$F$2:$F$2683= fylke) * ('data input'!$K$2:$K$2683 <> 0) * ('data input'!$H$2:$H$2683 = title)* ('data input'!$L$2:$L$2683= A2), 'data input'!$K$2:$K$2683))} -> 1045000 | C2: =IF(A2<>experience,experience!B2,NA()) -> 1045000 | D2: =IF(A2=experience,experience!B2,NA()) -> #N/A | F2: {=_xlfn._xlws.SORT(_xlfn._xlws.FILTER(A2:B5,ISNUMBER(B2:B5)),2,-1)} -> 9 - 14 | G2: 1075000 | I2: =IF(F2<>experience,experience!G2,NA()) -> #N/A | J2: =IF(F2=experience,experience!G2,NA()) -> 1075000
A3: 9 - 14 | B3: {=MEDIAN( IF( ('data input'!$F$2:$F$2683= fylke) * ('data input'!$K$2:$K$2683 <> 0) * ('data input'!$H$2:$H$2683 = title)* ('data input'!$L$2:$L$2683= A3), 'data input'!$K$2:$K$2683))} -> 1075000 | C3: =IF(A3<>experience,experience!B3,NA()) -> #N/A | D3: =IF(A3=experience,experience!B3,NA()) -> 1075000 | F3: 15 + | G3: 1045000 | I3: =IF(F3<>experience,experience!G3,NA()) -> 1045000 | J3: =IF(F3=experience,experience!G3,NA()) -> #N/A
A4: 5 - 8 | B4: {=MEDIAN( IF( ('data input'!$F$2:$F$2683= fylke) * ('data input'!$K$2:$K$2683 <> 0) * ('data input'!$H$2:$H$2683 = title)* ('data input'!$L$2:$L$2683= A4), 'data input'!$K$2:$K$2683))} -> 930000 | C4: =IF(A4<>experience,experience!B4,NA()) -> 930000 | D4: =IF(A4=experience,experience!B4,NA()) -> #N/A | F4: 5 - 8 | G4: 930000 | I4: =IF(F4<>experience,experience!G4,NA()) -> 930000 | J4: =IF(F4=experience,experience!G4,NA()) -> #N/A
A5: 0 - 4 | B5: {=MEDIAN( IF( ('data input'!$F$2:$F$2683= fylke) * ('data input'!$K$2:$K$2683 <> 0) * ('data input'!$H$2:$H$2683 = title)* ('data input'!$L$2:$L$2683= A5), 'data input'!$K$2:$K$2683))} -> 700000 | C5: =IF(A5<>experience,experience!B5,NA()) -> 700000 | D5: =IF(A5=experience,experience!B5,NA()) -> #N/A | F5: 0 - 4 | G5: 700000 | I5: =IF(F5<>experience,experience!G5,NA()) -> 700000 | J5: =IF(F5=experience,experience!G5,NA()) -> #N/A

Sheet job type
A1: Job types | B1: Number of jobs perspecialization | H1: Most popular type
A2: {=_xlfn.UNIQUE('data input'!G2:G2683)} -> "in-house: privat sektor" | B2: {=COUNT( IF( ('data input'!$F$2:$F$2683= fylke) * ('data input'!$K$2:$K$2683 <>0) * ('data input'!$H$2:$H$2683 = title)* ('data input'!$L$2:$L$2683= experience)* ('data input'!G:G = 'job type'!A2), 'data input'!$K$2:$K$2683))} -> 18 | D2: {=_xlfn._xlws.SORT(A2:B5,2, - 1)} -> konsulent | E2: 34 | F2: =(SUBSTITUTE(D2,"""","")) -> konsulent | H2: =F2 -> konsulent
A3: "in-house: offentlig/kommunal sektor" | B3: {=COUNT( IF( ('data input'!$F$2:$F$2683= fylke) * ('data input'!$K$2:$K$2683 <>0) * ('data input'!$H$2:$H$2683 = title)* ('data input'!$L$2:$L$2683= experience)* ('data input'!G:G = 'job type'!A3), 'data input'!$K$2:$K$2683))} -> 6 | D3: "in-house: privat sektor" | E3: 18 | F3: =(SUBSTITUTE(D3,"""","")) -> in-house: privat sektor
A4: konsulent | B4: {=COUNT( IF( ('data input'!$F$2:$F$2683= fylke) * ('data input'!$K$2:$K$2683 <>0) * ('data input'!$H$2:$H$2683 = title)* ('data input'!$L$2:$L$2683= experience)* ('data input'!G:G = 'job type'!A4), 'data input'!$K$2:$K$2683))} -> 34 | D4: "in-house: offentlig/kommunal sektor" | E4: 6 | F4: =(SUBSTITUTE(D4,"""","")) -> in-house: offentlig/kommunal sektor
A5: frilans / selvstendig næringsdrivende | B5: {=COUNT( IF( ('data input'!$F$2:$F$2683= fylke) * ('data input'!$K$2:$K$2683 <>0) * ('data input'!$H$2:$H$2683 = title)* ('data input'!$L$2:$L$2683= experience)* ('data input'!G:G = 'job type'!A5), 'data input'!$K$2:$K$2683))} -> 5 | D5: frilans / selvstendig næringsdrivende | E5: 5 | F5: =(SUBSTITUTE(D5,"""","")) -> frilans / selvstendig næringsdrivende
B7: =SUM(B2:B5) -> 63
